Workbook

Sheet Инструкция
A1: Набор вопросов для оценки RAG-бота (ООО «ТехноЛайн», вымышленные документы)
A3: Как заполнять
A4: 1. Перед прогоном запишите конфигурацию на листе «Прогоны» (модель, Chunk Size, Overlap, Limit).
A5: 2. На листе «Вопросы» задавайте каждый вопрос в НОВОЙ сессии чата. Исключение — вопросы 1 и 15 (одна сессия s01, подряд).
A6: 3. Заполняйте только жёлтые колонки: фактический ответ, три оценки (0 или 1) и комментарий.
A7: 4. Итоги внизу листа «Вопросы» считаются автоматически — перенесите их в строку прогона на листе «Прогоны».
A8: 5. Для следующего прогона сделайте копию листа «Вопросы» (ПКМ по вкладке → Переместить/скопировать) и очистите жёлтые колонки.
A10: Правила оценки (0 или 1)
A11: correct — все ключевые факты эталона есть и нет неверных. Частично верный ответ = 0, причина в комментарии.
A12: source_ok — верные файл и страница; для вопросов 9–11 нужны все источники; для 12–14 ссылки на источник быть не должно.
A13: no_hallucination — нет фактов, которых нет в документах (в №14 «5 дней на обучение» = 0).
A15: Что писать в комментарий при ошибке
... A31: source_ok: ответ без номера страницы = 0 (PDF-загрузчик передаёт страницу в метаданных).

Sheet Прогоны
A1: Прогон | B1: Дата | C1: Модель | D1: Chunk Size | E1: Overlap | F1: Limit (top-k) | G1: correct | H1: source_ok | I1: no_hallucination | J1: Сумма (из 45) | K1: Выводы
A2: пример | B2: 05.10.2026 | C2: gemini-3.5-flash-lite | D2: 800 | E2: 150 | F2: 4 | G2: 12 | H2: 10 | I2: 14 | J2: =IF(COUNT(G2:I2)=0,"",SUM(G2:I2)) -> 36
A3: 1 | C3: gemini-3.5-flash-lite | D3: 800 | E3: 150 | F3: 4 | G3: ='Вопросы 1'!H18 -> 14 | H3: ='Вопросы 1'!I18 -> 13 | I3: ='Вопросы 1'!J18 -> 15 | J3: =IF(COUNT(G3:I3)=0,"",SUM(G3:I3)) -> 42 | K3: Лучший результат. Единственная ошибка поиска — №9 (второй документ не найден). №14: источник при отказе.
A4: 2 | C4: gemini-3.5-flash-lite | D4: 400 | E4: 80 | F4: 4 | G4: ='Вопросы 2'!H18 -> 14 | H4: ='Вопросы 2'!I18 -> 11 | I4: ='Вопросы 2'!J18 -> 15 | J4: =IF(COUNT(G4:I4)=0,"",SUM(G4:I4)) -> 40 | K4: Поиск почти не изменился (№9 хуже — VPN пропал). Начала пропадать страница в источнике (3 случая).
A5: 3 | C5: gemini-3.5-flash-lite | D5: 200 | E5: 40 | F5: 4 | G5: ='Вопросы 3'!H18 -> 13 | H5: ='Вопросы 3'!I18 -> 5 | I5: ='Вопросы 3'!J18 -> 15 | J5: =IF(COUNT(G5:I5)=0,"",SUM(G5:I5)) -> 33 | K5: Хуже всего: №8 не найден (перефразирование), страницы теряются или неверны в 10 из 15. Мелкие фрагменты не подходят.
A6: 4 | C6: gemini-3.5-flash-lite | D6: 800 | E6: 150 | F6: 2 | G6: ='Вопросы 4'!H18 -> 14 | H6: ='Вопросы 4'!I18 -> 13 | I6: ='Вопросы 4'!J18 -> 15 | J6: =IF(COUNT(G6:I6)=0,"",SUM(G6:I6)) -> 42 | K6: Как прогон 1 (42). Даже 2 фрагментов хватило: база маленькая, вопросы в основном «один факт — одна страница». Ошибки те же: №9 и источник при отказе в №14.
A7: 5 | C7: gemini-3.5-flash-lite | D7: 800 | E7: 150 | F7: 8 | G7: ='Вопросы 5'!H18 -> 14 | H7: ='Вопросы 5'!I18 -> 14 | I7: ='Вопросы 5'!J18 -> 15 | J7: =IF(COUNT(G7:I7)=0,"",SUM(G7:I7)) -> 43 | K7: 43 — лучший, но +1 только за №14 (случайность модели). №9 не исправился даже при 8 из ~10–12 фрагментов базы → проблема не в поиске, а в модели/запросе агента.
A8: 6 | C8: gemini-3.6-flash | D8: 800 | E8: 150 | F8: 4 | G8: ='Вопросы 6'!H18 -> 14 | H8: ='Вопросы 6'!I18 -> 13 | I8: ='Вопросы 6'!J18 -> 15 | J8: =IF(COUNT(G8:I8)=0,"",SUM(G8:I8)) -> 42 | K8: 42 — не лучше flash-lite, при цене в ~5 раз выше. №9 не исправлен, появилась ошибка в имени файла и Markdown. Вывод: проблемы в промпте/поведении агента, а не в модели. Остаёмся на flash-lite.
A9: 7 | C9: gemini-3.5-flash-lite | D9: 800 | E9: 150 | F9: 4 | G9: ='Вопросы 7'!H18 -> 14 | H9: ='Вопросы 7'!I18 -> 14 | I9: ='Вопросы 7'!J18 -> 15 | J9: =IF(COUNT(G9:I9)=0,"",SUM(G9:I9)) -> 43 | K9: 43. Промпт v2: источник при отказе, искажение имени файла и Markdown исчезли. №9 не исправлен.
A10: 8 | C10: gemini-3.5-flash-lite | D10: 800 | E10: 150 | F10: 4 | G10: ='Вопросы 8'!H18 -> 14 | H10: ='Вопросы 8'!I18 -> 14 | I10: ='Вопросы 8'!J18 -> 15 | J10: =IF(COUNT(G10:I10)=0,"",SUM(G10:I10)) -> 43 | K10: 43 — результат повторился ответ в ответ: конфигурация стабильна. ИТОГОВАЯ КОНФИГУРАЦИЯ.
A12: Жёлтые ячейки заполняются после каждого прогона. «лучший» — подставьте значение из лучшего предыдущего прогона. Строка «пример» показывает формат.

Sheet Вопросы 1
A1: № | B1: Категория | C1: Сессия | D1: Вопрос | E1: Эталонный ответ | F1: Ожидаемый источник | G1: Фактический ответ | H1: correct | I1: source_ok | J1: no_hallucination | K1: Комментарий
A2: 1 | B2: прямой факт | C2: s01 | D2: Сколько календарных дней длится основной ежегодный отпуск? | E2: 28 календарных дней. | F2: reglament_otpuskov.pdf, стр. 1 | G2: Продолжительность ежегодного основного оплачиваемого отпуска составляет 28 календарных дней. Источник: reglament_otpuskov.pdf, стр. 1 | H2: 1 | I2: 1 | J2: 1
A3: 2 | B3: прямой факт | C3: s02 | D3: До какой даты утверждается график отпусков? | E3: Не позднее 15 декабря текущего года (на следующий год), утверждает генеральный директор. | F3: reglament_otpuskov.pdf, стр. 2 | G3: График отпусков на следующий календарный год утверждается генеральным директором не позднее 15 декабря текущего года. Источник: reglament_otpuskov.pdf, стр. 2 | H3: 1 | I3: 1 | J3: 1
A4: 3 | B4: прямой факт | C4: s03 | D4: Какие требования к длине пароля и как часто его нужно менять? | E4: Не менее 12 символов (заглавные, строчные буквы и цифры); смена каждые 90 дней; нельзя повторять 5 последних паролей. | F4: it_faq.pdf, стр. 1 | G4: Требования к паролю: * Пароль должен содержать не менее 12 символов, включая заглавные и строчные буквы и цифры. * Пароль нужно менять каждые 90 дней. * Нельзя повторять пять последних паролей. Источник: it_faq.pdf, стр. 1 | H4: 1 | I4: 1 | J4: 1
A5: 4 | B5: прямой факт | C5: s04 | D5: Какие дни считаются командными при гибридном формате? | E5: Вторник и четверг — присутствие в офисе обязательно; всего не менее двух офисных дней в неделю. | F5: politika_udalennoy_raboty.pdf, стр. 1 | G5: При гибридном формате работы вторник и четверг являются командными днями, в которые присутствие в офисе обязательно. Источник: politika_udalennoy_raboty.pdf, стр. 1 | H5: 1 | I5: 1 | J5: 1
A6: 5 | B6: прямой факт | C6: s05 | D6: Какой срок реакции ServiceDesk на заявку о сломанном ноутбуке? | E6: 4 рабочих часа; заявка в категории «Оборудование». | F6: it_faq.pdf, стр. 3 | G6: Срок реакции ServiceDesk на заявку о сломанном ноутбуке составляет 4 рабочих часа. Источник: it_faq.pdf, стр. 3 | H6: 1 | I6: 1 | J6: 1
A7: 6 | B7: перефразирование | C7: s06 | D7: Когда мне перечислят деньги за отпуск? | E7: Отпускные перечисляются на зарплатную карту не позднее чем за 3 календарных дня до начала отпуска. | F7: reglament_otpuskov.pdf, стр. 3 | G7: Оплата отпуска (отпускные) перечисляется на зарплатную карту сотрудника не позднее чем за 3 календарных дня до начала отпуска. Источник: reglament_otpuskov.pdf, стр. 3 | H7: 1 | I7: 1 | J7: 1
A8: 7 | B8: перефразирование | C8: s07 | D8: Можно забрать экран из офиса, чтобы работать дома? | E8: Да, сотрудник гибридного или удалённого формата может забрать один монитор по акту передачи оборудования. | F8: it_faq.pdf, стр. 3 | G8: Да, сотрудник гибридного или удалённого формата может забрать домой один монитор из офиса по акту передачи оборудования. Источник: it_faq.pdf, стр. 3 | H8: 1 | I8: 1 | J8: 1
A9: 8 | B9: перефразирование | C9: s08 | D9: У меня украли смартфон, на котором стоит приложение для входа в почту. Что делать? | E9: Немедленно позвонить на линию поддержки по внутреннему номеру 4444 (круглосуточно): заблокируют старое устройство и помогут привязать новое. | F9: it_faq.pdf, стр. 2 | G9: Немедленно позвоните на линию поддержки по внутреннему номеру 4444 (работает круглосуточно). Специалист заблокирует старое устройство и поможет привязать новое. Источник: it_faq.pdf, стр. 2 | H9: 1 | I9: 1 | J9: 1
A10: 9 | B10: несколько фрагментов | C10: s09 | D10: Хочу месяц поработать из Испании. Можно ли и что для этого нужно? | E10: Можно не более 30 календарных дней в году (месяц из 31 дня уже превышает лимит); согласовать с HR и службой ИБ не позднее чем за 10 рабочих дней; подключаться только через VPN (клиент «TL Connect», заявка в ServiceDesk, «Доступы», выдаётся за 1 рабочий день). | F10: politika_udalennoy_raboty.pdf, стр. 3; it_faq.pdf, стр. 2 | G10: Да, работать из-за рубежа (в том числе из Испании) допускается, но не более 30 календарных дней в течение календарного года. Что для этого нужно: 1. Согласовать поездку с HR-отделом и службой информационной безопасности не позднее чем за 10 рабочих дней до её начала. 2. Подключаться к корпоративным системам за пределами офиса только через корпоративный VPN. Источник: politika_udalennoy_raboty.pdf, стр. 3 | H10: 0 | I10: 0 | J10: 1 | K10: фрагмент не найден: нет it_faq.pdf, стр. 2 (как получить VPN — TL Connect, заявка в ServiceDesk); источник указан только один
A11: 10 | B11: несколько фрагментов | C11: s10 | D11: За сколько нужно подать заявку на отпуск и за сколько — на разовый удалённый день? | E11: Отпуск — не позднее чем за 14 календарных дней; разовый удалённый день — не позднее чем за 1 рабочий день. | F11: reglament_otpuskov.pdf, стр. 2; politika_udalennoy_raboty.pdf, стр. 2 | G11: Заявление на отпуск нужно подать в HR-портале не позднее чем за 14 календарных дней до даты начала отпуска. Заявка на разовый удалённый день подаётся не позднее чем за 1 рабочий день. Источники: - reglament_otpuskov.pdf, стр. 2 - politika_udalennoy_raboty.pdf, стр. 2 | H11: 1 | I11: 1 | J11: 1
A12: 11 | B12: несколько фрагментов | C12: s11 | D12: Когда можно перейти на полностью удалённую работу и какие компенсации при этом положены? | E12: После успешного испытательного срока и по согласованию с директором по направлению; компенсация интернета 1 500 руб. в месяц (вместе с зарплатой). | F12: politika_udalennoy_raboty.pdf, стр. 1; politika_udalennoy_raboty.pdf, стр. 2 | G12: Переход на полностью удалённый формат возможен только после успешного прохождения испытательного срока и по согласованию с директором по направлению. Данный формат фиксируется в дополнительном соглашении к трудовому договору. При полностью удалённом формате работы компания компенсирует расходы на домашний интернет в размере 1 500 рублей в месяц (компенсация выплачивается вместе с заработной платой). Источник: politika_udalennoy_raboty.pdf, стр. 1, 2 | H12: 1 | I12: 1 | J12: 1
A13: 12 | B13: вне документов | C13: s12 | D13: Положен ли сотрудникам полис ДМС? | E13: Не знаю — в документах нет информации об этом. | F13: — | G13: Не знаю — в документах нет информации об этом. | H13: 1 | I13: 1 | J13: 1
A14: 13 | B14: вне документов | C14: s13 | D14: Сколько стоит парковка у офиса? | E14: Не знаю — в документах нет информации об этом. | F14: — | G14: Не знаю — в документах нет информации об этом. | H14: 1 | I14: 1 | J14: 1
A15: 14 | B15: вне документов (ловушка) | C15: s14 | D15: Сколько дней отпуска без сохранения зарплаты можно взять на обучение? | E15: В документах нет информации об отпуске на обучение. Допустимо упомянуть, что по семейным обстоятельствам дают до 5 дней, но нельзя выдавать это за ответ про обучение. | F15: — (рядом: reglament_otpuskov.pdf, стр. 2) | G15: Не знаю — в документах нет информации об этом. Источник: reglament_otpuskov.pdf | H15: 1 | I15: 0 | J15: 1 | K15: ответ верный, но к отказу приложен источник — нарушение правила промпта (не модель и не поиск)
A16: 15 | B16: память (после вопроса 1) | C16: s01 | D16: А для стажёров? | E16: Пропорционально отработанному времени: 2,33 календарного дня за каждый полный отработанный месяц. | F16: reglament_otpuskov.pdf, стр. 3 | G16: Стажёрам (сотрудникам по договору стажировки) отпуск предоставляется пропорционально отработанному времени — 2,33 календарного дня за каждый полный отработанный месяц. Источник: reglament_otpuskov.pdf, стр. 3 | H16: 1 | I16: 1 | J16: 1
G18: Итого (из 15) | H18: =SUM(H2:H16) -> 14 | I18: =SUM(I2:I16) -> 13 | J18: =SUM(J2:J16) -> 15
G19: Доля | H19: =IF(COUNT(H2:H16)=0,"",SUM(H2:H16)/COUNT(H2:H16)) -> 0.93333333 | I19: =IF(COUNT(I2:I16)=0,"",SUM(I2:I16)/COUNT(I2:I16)) -> 0.86666667 | J19: =IF(COUNT(J2:J16)=0,"",SUM(J2:J16)/COUNT(J2:J16)) -> 1
G20: Заполнено | H20: =COUNT(H2:H16) -> 15 | I20: =COUNT(I2:I16) -> 15 | J20: =COUNT(J2:J16) -> 15

Sheet Вопросы 2
A1: № | B1: Категория | C1: Сессия | D1: Вопрос | E1: Эталонный ответ | F1: Ожидаемый источник | G1: Фактический ответ | H1: correct | I1: source_ok | J1: no_hallucination | K1: Комментарий
A2: 1 | B2: прямой факт | C2: s01 | D2: Сколько календарных дней длится основной ежегодный отпуск? | E2: 28 календарных дней. | F2: reglament_otpuskov.pdf, стр. 1 | G2: Основной ежегодный отпуск длится 28 календарных дней. Источник: reglament_otpuskov.pdf | H2: 1 | I2: 0 | J2: 1 | K2: страница не указана (файл верный)
A3: 2 | B3: прямой факт | C3: s02 | D3: До какой даты утверждается график отпусков? | E3: Не позднее 15 декабря текущего года (на следующий год), утверждает генеральный директор. | F3: reglament_otpuskov.pdf, стр. 2 | G3: График отпусков утверждается не позднее 15 декабря текущего года. Источник: reglament_otpuskov.pdf, стр. 2 | H3: 1 | I3: 1 | J3: 1
A4: 3 | B4: прямой факт | C4: s03 | D4: Какие требования к длине пароля и как часто его нужно менять? | E4: Не менее 12 символов (заглавные, строчные буквы и цифры); смена каждые 90 дней; нельзя повторять 5 последних паролей. | F4: it_faq.pdf, стр. 1 | G4: Требования к паролю: * Длина: не менее 12 символов. * Сложность: должен включать заглавные и строчные буквы, а также цифры. * Периодичность смены: каждые 90 дней. * Дополнительно: нельзя повторять пять последних паролей. Источник: it_faq.pdf, стр. 1 | H4: 1 | I4: 1 | J4: 1
A5: 4 | B5: прямой факт | C5: s04 | D5: Какие дни считаются командными при гибридном формате? | E5: Вторник и четверг — присутствие в офисе обязательно; всего не менее двух офисных дней в неделю. | F5: politika_udalennoy_raboty.pdf, стр. 1 | G5: При гибридном формате командными днями являются вторник и четверг — в эти дни присутствие в офисе обязательно. Источник: politika_udalennoy_raboty.pdf, стр. 1 | H5: 1 | I5: 1 | J5: 1
A6: 5 | B6: прямой факт | C6: s05 | D6: Какой срок реакции ServiceDesk на заявку о сломанном ноутбуке? | E6: 4 рабочих часа; заявка в категории «Оборудование». | F6: it_faq.pdf, стр. 3 | G6: Срок реакции ServiceDesk на заявку о сломанном ноутбуке составляет 4 рабочих часа. Источник: it_faq.pdf | H6: 1 | I6: 0 | J6: 1 | K6: страница не указана (файл верный)
A7: 6 | B7: перефразирование | C7: s06 | D7: Когда мне перечислят деньги за отпуск? | E7: Отпускные перечисляются на зарплатную карту не позднее чем за 3 календарных дня до начала отпуска. | F7: reglament_otpuskov.pdf, стр. 3 | G7: Оплата отпуска (отпускные) перечисляется на зарплатную карту сотрудника не позднее чем за 3 календарных дня до начала отпуска. Источник: reglament_otpuskov.pdf, стр. 3 | H7: 1 | I7: 1 | J7: 1
A8: 7 | B8: перефразирование | C8: s07 | D8: Можно забрать экран из офиса, чтобы работать дома? | E8: Да, сотрудник гибридного или удалённого формата может забрать один монитор по акту передачи оборудования. | F8: it_faq.pdf, стр. 3 | G8: Да, сотрудник гибридного или удалённого формата может забрать домой один монитор (экран) из офиса по акту передачи оборудования. Источник: it_faq.pdf, стр. 3 | H8: 1 | I8: 1 | J8: 1
A9: 8 | B9: перефразирование | C9: s08 | D9: У меня украли смартфон, на котором стоит приложение для входа в почту. Что делать? | E9: Немедленно позвонить на линию поддержки по внутреннему номеру 4444 (круглосуточно): заблокируют старое устройство и помогут привязать новое. | F9: it_faq.pdf, стр. 2 | G9: Немедленно позвоните на линию поддержки по внутреннему номеру 4444 (работает круглосуточно). Специалист заблокирует старое устройство и поможет привязать новое. Источник: it_faq.pdf, стр. 2 | H9: 1 | I9: 1 | J9: 1
A10: 9 | B10: несколько фрагментов | C10: s09 | D10: Хочу месяц поработать из Испании. Можно ли и что для этого нужно? | E10: Можно не более 30 календарных дней в году (месяц из 31 дня уже превышает лимит); согласовать с HR и службой ИБ не позднее чем за 10 рабочих дней; подключаться только через VPN (клиент «TL Connect», заявка в ServiceDesk, «Доступы», выдаётся за 1 рабочий день). | F10: politika_udalennoy_raboty.pdf, стр. 3; it_faq.pdf, стр. 2 | G10: Да, поработать из-за рубежа (в том числе из Испании) можно, так как работа из-за пределов Российской Федерации допускается на срок не более 30 календарных дней в течение календарного года. Что для этого нужно: * Согласовать поездку с HR-отделом и службой информационной безопасности. * Сделать это необходимо не позднее чем за 10 рабочих дней до её начала. Источник: politika_udalennoy_raboty.pdf, стр. 3 | H10: 0 | I10: 0 | J10: 1 | K10: фрагмент не найден: нет VPN вообще (ни требования, ни it_faq.pdf, стр. 2); источник один
A11: 10 | B11: несколько фрагментов | C11: s10 | D11: За сколько нужно подать заявку на отпуск и за сколько — на разовый удалённый день? | E11: Отпуск — не позднее чем за 14 календарных дней; разовый удалённый день — не позднее чем за 1 рабочий день. | F11: reglament_otpuskov.pdf, стр. 2; politika_udalennoy_raboty.pdf, стр. 2 | G11: Заявку на отпуск нужно подать не позднее чем за 14 календарных дней до даты начала отпуска (при переносе отпуска по графику — не позднее чем за 7 календарных дней). Заявку на разовый удалённый день нужно подать не позднее чем за 1 рабочий день. Источники: - reglament_otpuskov.pdf, стр. 2 - politika_udalennoy_raboty.pdf, стр. 2 | H11: 1 | I11: 1 | J11: 1 | K11: добавлен срок переноса отпуска (7 дней) — это есть в документе, не галлюцинация
A12: 11 | B12: несколько фрагментов | C12: s11 | D12: Когда можно перейти на полностью удалённую работу и какие компенсации при этом положены? | E12: После успешного испытательного срока и по согласованию с директором по направлению; компенсация интернета 1 500 руб. в месяц (вместе с зарплатой). | F12: politika_udalennoy_raboty.pdf, стр. 1; politika_udalennoy_raboty.pdf, стр. 2 | G12: Перейти на полностью удалённый формат работы можно **только после успешного прохождения испытательного срока** и **по согласованию с директором по направлению**. При этом сотрудникам полностью удалённого формата компания **компенсирует расходы на домашний интернет в размере 1 500 рублей в месяц** (выплачивается вместе с заработной платой). Источник: politika_udalennoy_raboty.pdf, стр. 1, 2 | H12: 1 | I12: 1 | J12: 1
A13: 12 | B13: вне документов | C13: s12 | D13: Положен ли сотрудникам полис ДМС? | E13: Не знаю — в документах нет информации об этом. | F13: — | G13: Не знаю — в документах нет информации об этом. | H13: 1 | I13: 1 | J13: 1
A14: 13 | B14: вне документов | C14: s13 | D14: Сколько стоит парковка у офиса? | E14: Не знаю — в документах нет информации об этом. | F14: — | G14: Не знаю — в документах нет информации об этом. | H14: 1 | I14: 1 | J14: 1
A15: 14 | B15: вне документов (ловушка) | C15: s14 | D15: Сколько дней отпуска без сохранения зарплаты можно взять на обучение? | E15: В документах нет информации об отпуске на обучение. Допустимо упомянуть, что по семейным обстоятельствам дают до 5 дней, но нельзя выдавать это за ответ про обучение. | F15: — (рядом: reglament_otpuskov.pdf, стр. 2) | G15: Не знаю — в документах нет информации об этом. | H15: 1 | I15: 1 | J15: 1
A16: 15 | B16: память (после вопроса 1) | C16: s01 | D16: А для стажёров? | E16: Пропорционально отработанному времени: 2,33 календарного дня за каждый полный отработанный месяц. | F16: reglament_otpuskov.pdf, стр. 3 | G16: Стажёрам (сотрудникам по договору стажировки) отпуск предоставляется пропорционально отработанному времени — из расчёта 2,33 календарного дня за каждый полный отработанный месяц. Источник: reglament_otpuskov.pdf | H16: 1 | I16: 0 | J16: 1 | K16: страница не указана (файл верный)
G18: Итого (из 15) | H18: =SUM(H2:H16) -> 14 | I18: =SUM(I2:I16) -> 11 | J18: =SUM(J2:J16) -> 15
G19: Доля | H19: =IF(COUNT(H2:H16)=0,"",SUM(H2:H16)/COUNT(H2:H16)) -> 0.93333333 | I19: =IF(COUNT(I2:I16)=0,"",SUM(I2:I16)/COUNT(I2:I16)) -> 0.73333333 | J19: =IF(COUNT(J2:J16)=0,"",SUM(J2:J16)/COUNT(J2:J16)) -> 1
G20: Заполнено | H20: =COUNT(H2:H16) -> 15 | I20: =COUNT(I2:I16) -> 15 | J20: =COUNT(J2:J16) -> 15

Sheet Вопросы 3
A1: № | B1: Категория | C1: Сессия | D1: Вопрос | E1: Эталонный ответ | F1: Ожидаемый источник | G1: Фактический ответ | H1: correct | I1: source_ok | J1: no_hallucination | K1: Комментарий
A2: 1 | B2: прямой факт | C2: s01 | D2: Сколько календарных дней длится основной ежегодный отпуск? | E2: 28 календарных дней. | F2: reglament_otpuskov.pdf, стр. 1 | G2: Основной ежегодный оплачиваемый отпуск длится 28 календарных дней. Источник: reglament_otpuskov.pdf | H2: 1 | I2: 0 | J2: 1 | K2: страница не указана (файл верный)
A3: 2 | B3: прямой факт | C3: s02 | D3: До какой даты утверждается график отпусков? | E3: Не позднее 15 декабря текущего года (на следующий год), утверждает генеральный директор. | F3: reglament_otpuskov.pdf, стр. 2 | G3: График отпусков утверждается генеральным директором не позднее 15 декабря текущего года. Источник: reglament_otpuskov.pdf | H3: 1 | I3: 0 | J3: 1 | K3: страница не указана (файл верный)
A4: 3 | B4: прямой факт | C4: s03 | D4: Какие требования к длине пароля и как часто его нужно менять? | E4: Не менее 12 символов (заглавные, строчные буквы и цифры); смена каждые 90 дней; нельзя повторять 5 последних паролей. | F4: it_faq.pdf, стр. 1 | G4: Пароль должен содержать не менее 12 символов, включая заглавные и строчные буквы и цифры. Менять его нужно каждые 90 дней. Источник: it_faq.pdf, стр. 1 | H4: 1 | I4: 1 | J4: 1
A5: 4 | B5: прямой факт | C5: s04 | D5: Какие дни считаются командными при гибридном формате? | E5: Вторник и четверг — присутствие в офисе обязательно; всего не менее двух офисных дней в неделю. | F5: politika_udalennoy_raboty.pdf, стр. 1 | G5: При гибридном формате командными днями являются вторник и четверг — в эти дни присутствие в офисе обязательно. Источник: politika_udalennoy_raboty.pdf, стр. 1 | H5: 1 | I5: 1 | J5: 1
A6: 5 | B6: прямой факт | C6: s05 | D6: Какой срок реакции ServiceDesk на заявку о сломанном ноутбуке? | E6: 4 рабочих часа; заявка в категории «Оборудование». | F6: it_faq.pdf, стр. 3 | G6: Срок реакции ServiceDesk на заявку о сломанном ноутбуке (в категории «Оборудование») составляет 4 рабочих часа. Источник: it_faq.pdf | H6: 1 | I6: 0 | J6: 1 | K6: страница не указана (файл верный)
A7: 6 | B7: перефразирование | C7: s06 | D7: Когда мне перечислят деньги за отпуск? | E7: Отпускные перечисляются на зарплатную карту не позднее чем за 3 календарных дня до начала отпуска. | F7: reglament_otpuskov.pdf, стр. 3 | G7: Оплата отпуска (отпускные) перечисляется на зарплатную карту сотрудника не позднее чем за 3 календарных дня до начала отпуска. Источник: reglament_otpuskov.pdf, стр. 3 | H7: 1 | I7: 1 | J7: 1
A8: 7 | B8: перефразирование | C8: s07 | D8: Можно забрать экран из офиса, чтобы работать дома? | E8: Да, сотрудник гибридного или удалённого формата может забрать один монитор по акту передачи оборудования. | F8: it_faq.pdf, стр. 3 | G8: Да, сотрудник гибридного или удаленного формата может забрать домой один монитор из офиса по акту передачи оборудования. Источник: it_faq.pdf | H8: 1 | I8: 0 | J8: 1 | K8: страница не указана (файл верный)
A9: 8 | B9: перефразирование | C9: s08 | D9: У меня украли смартфон, на котором стоит приложение для входа в почту. Что делать? | E9: Немедленно позвонить на линию поддержки по внутреннему номеру 4444 (круглосуточно): заблокируют старое устройство и помогут привязать новое. | F9: it_faq.pdf, стр. 2 | G9: Не знаю — в документах нет информации об этом. | H9: 0 | I9: 0 | J9: 1 | K9: отказ на вопрос с ответом в документах: вероятно, фрагмент не найден (перефразирование + мелкие фрагменты) — проверить в логе search_docs
A10: 9 | B10: несколько фрагментов | C10: s09 | D10: Хочу месяц поработать из Испании. Можно ли и что для этого нужно? | E10: Можно не более 30 календарных дней в году (месяц из 31 дня уже превышает лимит); согласовать с HR и службой ИБ не позднее чем за 10 рабочих дней; подключаться только через VPN (клиент «TL Connect», заявка в ServiceDesk, «Доступы», выдаётся за 1 рабочий день). | F10: politika_udalennoy_raboty.pdf, стр. 3; it_faq.pdf, стр. 2 | G10: Да, поработать из Испании (из-за пределов Российской Федерации) в течение месяца можно. Для этого необходимо соблюдать следующие требования: 1. Срок работы из-за рубежа не должен превышать 30 календарных дней в течение календарного года. 2. Поездку необходимо согласовать с HR-отделом и службой информационной безопасности не позднее чем за 10 рабочих дней до её начала. 3. Подключение к корпоративным системам за пределами офиса разрешено только через корпоративный VPN. Источник: politika_udalennoy_raboty.pdf, стр. 3 | H10: 0 | I10: 0 | J10: 1 | K10: фрагмент не найден: нет it_faq.pdf, стр. 2 (как получить VPN); «в течение месяца можно» без оговорки, что 31 день > лимита
A11: 10 | B11: несколько фрагментов | C11: s10 | D11: За сколько нужно подать заявку на отпуск и за сколько — на разовый удалённый день? | E11: Отпуск — не позднее чем за 14 календарных дней; разовый удалённый день — не позднее чем за 1 рабочий день. | F11: reglament_otpuskov.pdf, стр. 2; politika_udalennoy_raboty.pdf, стр. 2 | G11: Заявку на отпуск нужно подать за 14 календарных дней до даты начала отпуска. Заявку на разовый удалённый день нужно подать не позднее чем за 1 рабочий день. Источник: reglament_otpuskov.pdf, стр. 1; politika_udalennoy_raboty.pdf, стр. 2 | H11: 1 | I11: 0 | J11: 1 | K11: неверная страница: отпуск — стр. 2, а указана стр. 1
A12: 11 | B12: несколько фрагментов | C12: s11 | D12: Когда можно перейти на полностью удалённую работу и какие компенсации при этом положены? | E12: После успешного испытательного срока и по согласованию с директором по направлению; компенсация интернета 1 500 руб. в месяц (вместе с зарплатой). | F12: politika_udalennoy_raboty.pdf, стр. 1; politika_udalennoy_raboty.pdf, стр. 2 | G12: Переход на полностью удалённый формат возможен только после успешного прохождения испытательного срока и по согласованию с директором по направлению. Сотрудникам полностью удалённого формата компания компенсирует расходы на домашний интернет в размере 1 500 рублей в месяц (компенсация выплачивается вместе с заработной платой). Источник: politika_udalennoy_raboty.pdf, стр. 1 | H12: 1 | I12: 0 | J12: 1 | K12: не указана стр. 2 (компенсация интернета), указана только стр. 1
A13: 12 | B13: вне документов | C13: s12 | D13: Положен ли сотрудникам полис ДМС? | E13: Не знаю — в документах нет информации об этом. | F13: — | G13: Не знаю — в документах нет информации об этом. | H13: 1 | I13: 1 | J13: 1
A14: 13 | B14: вне документов | C14: s13 | D14: Сколько стоит парковка у офиса? | E14: Не знаю — в документах нет информации об этом. | F14: — | G14: Не знаю — в документах нет информации об этом. | H14: 1 | I14: 1 | J14: 1
A15: 14 | B15: вне документов (ловушка) | C15: s14 | D15: Сколько дней отпуска без сохранения зарплаты можно взять на обучение? | E15: В документах нет информации об отпуске на обучение. Допустимо упомянуть, что по семейным обстоятельствам дают до 5 дней, но нельзя выдавать это за ответ про обучение. | F15: — (рядом: reglament_otpuskov.pdf, стр. 2) | G15: Не знаю — в документах нет информации об этом. Источник: reglament_otpuskov.pdf | H15: 1 | I15: 0 | J15: 1 | K15: ответ верный, но к отказу приложен источник — нарушение правила промпта
A16: 15 | B16: память (после вопроса 1) | C16: s01 | D16: А для стажёров? | E16: Пропорционально отработанному времени: 2,33 календарного дня за каждый полный отработанный месяц. | F16: reglament_otpuskov.pdf, стр. 3 | G16: Стажёрам (сотрудникам по договору стажировки) отпуск предоставляется пропорционально отработанному времени: 2,33 календарного дня за каждый полный отработанный месяц. Источник: reglament_otpuskov.pdf | H16: 1 | I16: 0 | J16: 1 | K16: страница не указана (файл верный)
G18: Итого (из 15) | H18: =SUM(H2:H16) -> 13 | I18: =SUM(I2:I16) -> 5 | J18: =SUM(J2:J16) -> 15
G19: Доля | H19: =IF(COUNT(H2:H16)=0,"",SUM(H2:H16)/COUNT(H2:H16)) -> 0.86666667 | I19: =IF(COUNT(I2:I16)=0,"",SUM(I2:I16)/COUNT(I2:I16)) -> 0.33333333 | J19: =IF(COUNT(J2:J16)=0,"",SUM(J2:J16)/COUNT(J2:J16)) -> 1
G20: Заполнено | H20: =COUNT(H2:H16) -> 15 | I20: =COUNT(I2:I16) -> 15 | J20: =COUNT(J2:J16) -> 15

Sheet Вопросы 4
A1: № | B1: Категория | C1: Сессия | D1: Вопрос | E1: Эталонный ответ | F1: Ожидаемый источник | G1: Фактический ответ | H1: correct | I1: source_ok | J1: no_hallucination | K1: Комментарий
A2: 1 | B2: прямой факт | C2: s01 | D2: Сколько календарных дней длится основной ежегодный отпуск? | E2: 28 календарных дней. | F2: reglament_otpuskov.pdf, стр. 1 | G2: Продолжительность ежегодного основного оплачиваемого отпуска составляет 28 календарных дней. Источник: reglament_otpuskov.pdf, стр. 1 | H2: 1 | I2: 1 | J2: 1
A3: 2 | B3: прямой факт | C3: s02 | D3: До какой даты утверждается график отпусков? | E3: Не позднее 15 декабря текущего года (на следующий год), утверждает генеральный директор. | F3: reglament_otpuskov.pdf, стр. 2 | G3: График отпусков утверждается не позднее 15 декабря текущего года. Источник: reglament_otpuskov.pdf, стр. 2 | H3: 1 | I3: 1 | J3: 1
A4: 3 | B4: прямой факт | C4: s03 | D4: Какие требования к длине пароля и как часто его нужно менять? | E4: Не менее 12 символов (заглавные, строчные буквы и цифры); смена каждые 90 дней; нельзя повторять 5 последних паролей. | F4: it_faq.pdf, стр. 1 | G4: Требования к паролю: * Пароль должен содержать не менее 12 символов, включая заглавные и строчные буквы, а также цифры. * Менять пароль нужно каждые 90 дней. Источник: it_faq.pdf, стр. 1 | H4: 1 | I4: 1 | J4: 1
A5: 4 | B5: прямой факт | C5: s04 | D5: Какие дни считаются командными при гибридном формате? | E5: Вторник и четверг — присутствие в офисе обязательно; всего не менее двух офисных дней в неделю. | F5: politika_udalennoy_raboty.pdf, стр. 1 | G5: При гибридном формате командными днями являются вторник и четверг — в эти дни присутствие в офисе обязательно. Источник: politika_udalennoy_raboty.pdf, стр. 1 | H5: 1 | I5: 1 | J5: 1
A6: 5 | B6: прямой факт | C6: s05 | D6: Какой срок реакции ServiceDesk на заявку о сломанном ноутбуке? | E6: 4 рабочих часа; заявка в категории «Оборудование». | F6: it_faq.pdf, стр. 3 | G6: Срок реакции ServiceDesk на заявку о сломанном ноутбуке составляет 4 рабочих часа. Источник: it_faq.pdf, стр. 3 | H6: 1 | I6: 1 | J6: 1
A7: 6 | B7: перефразирование | C7: s06 | D7: Когда мне перечислят деньги за отпуск? | E7: Отпускные перечисляются на зарплатную карту не позднее чем за 3 календарных дня до начала отпуска. | F7: reglament_otpuskov.pdf, стр. 3 | G7: Оплата отпуска (отпускные) перечисляется на зарплатную карту сотрудника не позднее чем за 3 календарных дня до начала отпуска. Источник: reglament_otpuskov.pdf, стр. 3 | H7: 1 | I7: 1 | J7: 1
A8: 7 | B8: перефразирование | C8: s07 | D8: Можно забрать экран из офиса, чтобы работать дома? | E8: Да, сотрудник гибридного или удалённого формата может забрать один монитор по акту передачи оборудования. | F8: it_faq.pdf, стр. 3 | G8: Да, сотрудник гибридного или удалённого формата может забрать домой один монитор из офиса по акту передачи оборудования. Источник: it_faq.pdf, стр. 3 | H8: 1 | I8: 1 | J8: 1
A9: 8 | B9: перефразирование | C9: s08 | D9: У меня украли смартфон, на котором стоит приложение для входа в почту. Что делать? | E9: Немедленно позвонить на линию поддержки по внутреннему номеру 4444 (круглосуточно): заблокируют старое устройство и помогут привязать новое. | F9: it_faq.pdf, стр. 2 | G9: Немедленно позвоните на линию поддержки по внутреннему номеру 4444 (работает круглосуточно). Специалист заблокирует старое устройство и поможет привязать новое. Источник: it_faq.pdf, стр. 2 | H9: 1 | I9: 1 | J9: 1
A10: 9 | B10: несколько фрагментов | C10: s09 | D10: Хочу месяц поработать из Испании. Можно ли и что для этого нужно? | E10: Можно не более 30 календарных дней в году (месяц из 31 дня уже превышает лимит); согласовать с HR и службой ИБ не позднее чем за 10 рабочих дней; подключаться только через VPN (клиент «TL Connect», заявка в ServiceDesk, «Доступы», выдаётся за 1 рабочий день). | F10: politika_udalennoy_raboty.pdf, стр. 3; it_faq.pdf, стр. 2 | G10: Да, поработать из-за рубежа (в том числе из Испании) можно, но не более 30 календарных дней в течение календарного года. Что для этого нужно: 1. Согласовать поездку с HR-отделом и службой информационной безопасности не позднее чем за 10 рабочих дней до её начала. 2. Подключаться к корпоративным системам из-за рубежа разрешено только через корпоративный VPN. Источник: politika_udalennoy_raboty.pdf, стр. 3 | H10: 0 | I10: 0 | J10: 1 | K10: фрагмент не найден/не использован: нет it_faq.pdf, стр. 2 (как получить VPN); источник один
A11: 10 | B11: несколько фрагментов | C11: s10 | D11: За сколько нужно подать заявку на отпуск и за сколько — на разовый удалённый день? | E11: Отпуск — не позднее чем за 14 календарных дней; разовый удалённый день — не позднее чем за 1 рабочий день. | F11: reglament_otpuskov.pdf, стр. 2; politika_udalennoy_raboty.pdf, стр. 2 | G11: Заявление на отпуск подаётся не позднее чем за 14 календарных дней до даты начала отпуска (перенос отпуска по графику — не позднее чем за 7 календарных дней). Заявка на разовый удалённый день подаётся не позднее чем за 1 рабочий день. Источник: reglament_otpuskov.pdf, стр. 2; politika_udalennoy_raboty.pdf, стр. 2 | H11: 1 | I11: 1 | J11: 1 | K11: оба документа найдены даже при Limit 2 — агент, видимо, делал два запроса; срок переноса (7 дней) есть в документе
A12: 11 | B12: несколько фрагментов | C12: s11 | D12: Когда можно перейти на полностью удалённую работу и какие компенсации при этом положены? | E12: После успешного испытательного срока и по согласованию с директором по направлению; компенсация интернета 1 500 руб. в месяц (вместе с зарплатой). | F12: politika_udalennoy_raboty.pdf, стр. 1; politika_udalennoy_raboty.pdf, стр. 2 | G12: Переход на полностью удалённый формат возможен только после успешного прохождения испытательного срока и по согласованию с директором по направлению. Сам формат работы фиксируется в дополнительном соглашении к трудовому договору. При этом сотрудникам полностью удалённого формата компания компенсирует расходы на домашний интернет в размере 1 500 рублей в месяц (выплачивается вместе с заработной платой). Источник: politika_udalennoy_raboty.pdf, стр. 1, 2 | H12: 1 | I12: 1 | J12: 1
A13: 12 | B13: вне документов | C13: s12 | D13: Положен ли сотрудникам полис ДМС? | E13: Не знаю — в документах нет информации об этом. | F13: — | G13: Не знаю — в документах нет информации об этом. | H13: 1 | I13: 1 | J13: 1
A14: 13 | B14: вне документов | C14: s13 | D14: Сколько стоит парковка у офиса? | E14: Не знаю — в документах нет информации об этом. | F14: — | G14: Не знаю — в документах нет информации об этом. | H14: 1 | I14: 1 | J14: 1
A15: 14 | B15: вне документов (ловушка) | C15: s14 | D15: Сколько дней отпуска без сохранения зарплаты можно взять на обучение? | E15: В документах нет информации об отпуске на обучение. Допустимо упомянуть, что по семейным обстоятельствам дают до 5 дней, но нельзя выдавать это за ответ про обучение. | F15: — (рядом: reglament_otpuskov.pdf, стр. 2) | G15: Не знаю — в документах нет информации об этом. Источник: reglament_otpuskov.pdf | H15: 1 | I15: 0 | J15: 1 | K15: ответ верный, но к отказу приложен источник — нарушение правила промпта
A16: 15 | B16: память (после вопроса 1) | C16: s01 | D16: А для стажёров? | E16: Пропорционально отработанному времени: 2,33 календарного дня за каждый полный отработанный месяц. | F16: reglament_otpuskov.pdf, стр. 3 | G16: Стажёрам (сотрудникам по договору стажировки) отпуск предоставляется пропорционально отработанному времени: 2,33 календарного дня за каждый полный отработанный месяц. Источник: reglament_otpuskov.pdf, стр. 3 | H16: 1 | I16: 1 | J16: 1
G18: Итого (из 15) | H18: =SUM(H2:H16) -> 14 | I18: =SUM(I2:I16) -> 13 | J18: =SUM(J2:J16) -> 15
G19: Доля | H19: =IF(COUNT(H2:H16)=0,"",SUM(H2:H16)/COUNT(H2:H16)) -> 0.93333333 | I19: =IF(COUNT(I2:I16)=0,"",SUM(I2:I16)/COUNT(I2:I16)) -> 0.86666667 | J19: =IF(COUNT(J2:J16)=0,"",SUM(J2:J16)/COUNT(J2:J16)) -> 1
G20: Заполнено | H20: =COUNT(H2:H16) -> 15 | I20: =COUNT(I2:I16) -> 15 | J20: =COUNT(J2:J16) -> 15

Sheet Вопросы 5
A1: № | B1: Категория | C1: Сессия | D1: Вопрос | E1: Эталонный ответ | F1: Ожидаемый источник | G1: Фактический ответ | H1: correct | I1: source_ok | J1: no_hallucination | K1: Комментарий
A2: 1 | B2: прямой факт | C2: s01 | D2: Сколько календарных дней длится основной ежегодный отпуск? | E2: 28 календарных дней. | F2: reglament_otpuskov.pdf, стр. 1 | G2: Продолжительность ежегодного основного оплачиваемого отпуска составляет 28 календарных дней. Источник: reglament_otpuskov.pdf, стр. 1 | H2: 1 | I2: 1 | J2: 1
A3: 2 | B3: прямой факт | C3: s02 | D3: До какой даты утверждается график отпусков? | E3: Не позднее 15 декабря текущего года (на следующий год), утверждает генеральный директор. | F3: reglament_otpuskov.pdf, стр. 2 | G3: График отпусков на следующий календарный год утверждается генеральным директором не позднее 15 декабря текущего года. Источник: reglament_otpuskov.pdf, стр. 2 | H3: 1 | I3: 1 | J3: 1
A4: 3 | B4: прямой факт | C4: s03 | D4: Какие требования к длине пароля и как часто его нужно менять? | E4: Не менее 12 символов (заглавные, строчные буквы и цифры); смена каждые 90 дней; нельзя повторять 5 последних паролей. | F4: it_faq.pdf, стр. 1 | G4: Требования к паролю: * Длина: не менее 12 символов. * Состав: должен содержать заглавные и строчные буквы, а также цифры. * Дополнительное требование: нельзя повторять пять последних паролей. Периодичность смены: * Пароль нужно менять каждые 90 дней. Источник: it_faq.pdf, стр. 1 | H4: 1 | I4: 1 | J4: 1
A5: 4 | B5: прямой факт | C5: s04 | D5: Какие дни считаются командными при гибридном формате? | E5: Вторник и четверг — присутствие в офисе обязательно; всего не менее двух офисных дней в неделю. | F5: politika_udalennoy_raboty.pdf, стр. 1 | G5: Вторник и четверг являются командными днями при гибридном формате — в эти дни присутствие в офисе обязательно. Источник: politika_udalennoy_raboty.pdf, стр. 1 | H5: 1 | I5: 1 | J5: 1
A6: 5 | B6: прямой факт | C6: s05 | D6: Какой срок реакции ServiceDesk на заявку о сломанном ноутбуке? | E6: 4 рабочих часа; заявка в категории «Оборудование». | F6: it_faq.pdf, стр. 3 | G6: Срок реакции ServiceDesk на заявку о сломанном ноутбуке составляет 4 рабочих часа. Источник: it_faq.pdf, стр. 3 | H6: 1 | I6: 1 | J6: 1
A7: 6 | B7: перефразирование | C7: s06 | D7: Когда мне перечислят деньги за отпуск? | E7: Отпускные перечисляются на зарплатную карту не позднее чем за 3 календарных дня до начала отпуска. | F7: reglament_otpuskov.pdf, стр. 3 | G7: Оплата отпуска (отпускные) перечисляется на зарплатную карту сотрудника не позднее чем за 3 календарных дня до начала отпуска. Источник: reglament_otpuskov.pdf, стр. 3 | H7: 1 | I7: 1 | J7: 1
A8: 7 | B8: перефразирование | C8: s07 | D8: Можно забрать экран из офиса, чтобы работать дома? | E8: Да, сотрудник гибридного или удалённого формата может забрать один монитор по акту передачи оборудования. | F8: it_faq.pdf, стр. 3 | G8: Да, сотрудник гибридного или удалённого формата может забрать домой один монитор из офиса по акту передачи оборудования. Источник: it_faq.pdf, стр. 3 | H8: 1 | I8: 1 | J8: 1
A9: 8 | B9: перефразирование | C9: s08 | D9: У меня украли смартфон, на котором стоит приложение для входа в почту. Что делать? | E9: Немедленно позвонить на линию поддержки по внутреннему номеру 4444 (круглосуточно): заблокируют старое устройство и помогут привязать новое. | F9: it_faq.pdf, стр. 2 | G9: Немедленно позвоните на линию поддержки по внутреннему номеру 4444 (работает круглосуточно). Специалист заблокирует старое устройство и поможет привязать новое. Источник: it_faq.pdf, стр. 2 | H9: 1 | I9: 1 | J9: 1
A10: 9 | B10: несколько фрагментов | C10: s09 | D10: Хочу месяц поработать из Испании. Можно ли и что для этого нужно? | E10: Можно не более 30 календарных дней в году (месяц из 31 дня уже превышает лимит); согласовать с HR и службой ИБ не позднее чем за 10 рабочих дней; подключаться только через VPN (клиент «TL Connect», заявка в ServiceDesk, «Доступы», выдаётся за 1 рабочий день). | F10: politika_udalennoy_raboty.pdf, стр. 3; it_faq.pdf, стр. 2 | G10: Да, работать из-за рубежа (в том числе из Испании) можно, но не более 30 календарных дней в течение календарного года. Что для этого нужно: 1. Согласовать поездку с HR-отделом и службой информационной безопасности не позднее чем за 10 рабочих дней до её начала. 2. Подключаться к корпоративным системам из-за рубежа только через корпоративный VPN. Источник: politika_udalennoy_raboty.pdf, стр. 3 | H10: 0 | I10: 0 | J10: 1 | K10: та же ошибка при Limit 8: при ~10–12 фрагментах в базе нужный почти наверняка был в выдаче → модель не использовала его (проверить в логе)
A11: 10 | B11: несколько фрагментов | C11: s10 | D11: За сколько нужно подать заявку на отпуск и за сколько — на разовый удалённый день? | E11: Отпуск — не позднее чем за 14 календарных дней; разовый удалённый день — не позднее чем за 1 рабочий день. | F11: reglament_otpuskov.pdf, стр. 2; politika_udalennoy_raboty.pdf, стр. 2 | G11: Заявление на отпуск подаётся не позднее чем за 14 календарных дней до даты начала отпуска. Заявка на разовый удалённый день подаётся не позднее чем за 1 рабочий день. Источник: reglament_otpuskov.pdf, стр. 2; politika_udalennoy_raboty.pdf, стр. 2 | H11: 1 | I11: 1 | J11: 1
A12: 11 | B12: несколько фрагментов | C12: s11 | D12: Когда можно перейти на полностью удалённую работу и какие компенсации при этом положены? | E12: После успешного испытательного срока и по согласованию с директором по направлению; компенсация интернета 1 500 руб. в месяц (вместе с зарплатой). | F12: politika_udalennoy_raboty.pdf, стр. 1; politika_udalennoy_raboty.pdf, стр. 2 | G12: Перевод на полностью удалённый формат возможен только после успешного прохождения испытательного срока и по согласованию с директором по направлению. Сотрудникам полностью удалённого формата компания компенсирует расходы на домашний интернет в размере 1 500 рублей в месяц (выплачивается вместе с заработной платой). Источник: politika_udalennoy_raboty.pdf, стр. 1–2 | H12: 1 | I12: 1 | J12: 1
A13: 12 | B13: вне документов | C13: s12 | D13: Положен ли сотрудникам полис ДМС? | E13: Не знаю — в документах нет информации об этом. | F13: — | G13: Не знаю — в документах нет информации об этом. | H13: 1 | I13: 1 | J13: 1
A14: 13 | B14: вне документов | C14: s13 | D14: Сколько стоит парковка у офиса? | E14: Не знаю — в документах нет информации об этом. | F14: — | G14: Не знаю — в документах нет информации об этом. | H14: 1 | I14: 1 | J14: 1
A15: 14 | B15: вне документов (ловушка) | C15: s14 | D15: Сколько дней отпуска без сохранения зарплаты можно взять на обучение? | E15: В документах нет информации об отпуске на обучение. Допустимо упомянуть, что по семейным обстоятельствам дают до 5 дней, но нельзя выдавать это за ответ про обучение. | F15: — (рядом: reglament_otpuskov.pdf, стр. 2) | G15: Не знаю — в документах нет информации об этом. | H15: 1 | I15: 1 | J15: 1 | K15: источник к отказу не приложен — вероятно, случайность модели, а не эффект Limit
A16: 15 | B16: память (после вопроса 1) | C16: s01 | D16: А для стажёров? | E16: Пропорционально отработанному времени: 2,33 календарного дня за каждый полный отработанный месяц. | F16: reglament_otpuskov.pdf, стр. 3 | G16: Стажёрам (сотрудникам по договору стажировки) отпуск предоставляется пропорционально отработанному времени: 2,33 календарного дня за каждый полный отработанный месяц. Источник: reglament_otpuskov.pdf, стр. 3 | H16: 1 | I16: 1 | J16: 1
G18: Итого (из 15) | H18: =SUM(H2:H16) -> 14 | I18: =SUM(I2:I16) -> 14 | J18: =SUM(J2:J16) -> 15
G19: Доля | H19: =IF(COUNT(H2:H16)=0,"",SUM(H2:H16)/COUNT(H2:H16)) -> 0.93333333 | I19: =IF(COUNT(I2:I16)=0,"",SUM(I2:I16)/COUNT(I2:I16)) -> 0.93333333 | J19: =IF(COUNT(J2:J16)=0,"",SUM(J2:J16)/COUNT(J2:J16)) -> 1
G20: Заполнено | H20: =COUNT(H2:H16) -> 15 | I20: =COUNT(I2:I16) -> 15 | J20: =COUNT(J2:J16) -> 15

Sheet Вопросы 6
A1: № | B1: Категория | C1: Сессия | D1: Вопрос | E1: Эталонный ответ | F1: Ожидаемый источник | G1: Фактический ответ | H1: correct | I1: source_ok | J1: no_hallucination | K1: Комментарий
A2: 1 | B2: прямой факт | C2: s01 | D2: Сколько календарных дней длится основной ежегодный отпуск? | E2: 28 календарных дней. | F2: reglament_otpuskov.pdf, стр. 1 | G2: Продолжительность ежегодного основного оплачиваемого отпуска составляет 28 календарных дней. Источник: reglament_otpuskov.pdf, стр. 1 | H2: 1 | I2: 1 | J2: 1
A3: 2 | B3: прямой факт | C3: s02 | D3: До какой даты утверждается график отпусков? | E3: Не позднее 15 декабря текущего года (на следующий год), утверждает генеральный директор. | F3: reglament_otpuskov.pdf, стр. 2 | G3: График отпусков на следующий календарный год утверждается генеральным директором не позднее 15 декабря текущего года. Источник: reglament_otpuskov.pdf, стр. 2 | H3: 1 | I3: 1 | J3: 1
A4: 3 | B4: прямой факт | C4: s03 | D4: Какие требования к длине пароля и как часто его нужно менять? | E4: Не менее 12 символов (заглавные, строчные буквы и цифры); смена каждые 90 дней; нельзя повторять 5 последних паролей. | F4: it_faq.pdf, стр. 1 | G4: Пароль должен содержать **не менее 12 символов** (включая заглавные и строчные буквы, а также цифры). Менять пароль необходимо **каждые 90 дней**. Источник: it_faq.pdf, стр. 1 | H4: 1 | I4: 1 | J4: 1 | K4: появилась Markdown-разметка (**…**) — в Telegram отобразится звёздочками
A5: 4 | B5: прямой факт | C5: s04 | D5: Какие дни считаются командными при гибридном формате? | E5: Вторник и четверг — присутствие в офисе обязательно; всего не менее двух офисных дней в неделю. | F5: politika_udalennoy_raboty.pdf, стр. 1 | G5: При гибридном формате командными днями являются **вторник** и **четверг** (в эти дни присутствие в офисе обязательно). Источник: politika_udalennoy_raboty.pdf, стр. 1 | H5: 1 | I5: 1 | J5: 1
A6: 5 | B6: прямой факт | C6: s05 | D6: Какой срок реакции ServiceDesk на заявку о сломанном ноутбуке? | E6: 4 рабочих часа; заявка в категории «Оборудование». | F6: it_faq.pdf, стр. 3 | G6: Срок реакции ServiceDesk на заявку о сломанном ноутбуке (в категории «Оборудование») составляет 4 рабочих часа. Источник: it_faq.pdf, стр. 3 | H6: 1 | I6: 1 | J6: 1
A7: 6 | B7: перефразирование | C7: s06 | D7: Когда мне перечислят деньги за отпуск? | E7: Отпускные перечисляются на зарплатную карту не позднее чем за 3 календарных дня до начала отпуска. | F7: reglament_otpuskov.pdf, стр. 3 | G7: Оплата отпуска (отпускные) перечисляется на вашу зарплатную карту не позднее чем за 3 календарных дня до начала отпуска. Источник: reglament_otpuskov.pdf, стр. 3 | H7: 1 | I7: 1 | J7: 1
A8: 7 | B8: перефразирование | C8: s07 | D8: Можно забрать экран из офиса, чтобы работать дома? | E8: Да, сотрудник гибридного или удалённого формата может забрать один монитор по акту передачи оборудования. | F8: it_faq.pdf, стр. 3 | G8: Да, сотрудник гибридного или удалённого формата может забрать домой один монитор из офиса по акту передачи оборудования. Источник: it_faq.pdf, стр. 3 | H8: 1 | I8: 1 | J8: 1
A9: 8 | B9: перефразирование | C9: s08 | D9: У меня украли смартфон, на котором стоит приложение для входа в почту. Что делать? | E9: Немедленно позвонить на линию поддержки по внутреннему номеру 4444 (круглосуточно): заблокируют старое устройство и помогут привязать новое. | F9: it_faq.pdf, стр. 2 | G9: Если вы потеряли телефон с приложением-аутентификатором (или его украли), вам необходимо: 1. Немедленно позвонить на линию поддержки по внутреннему номеру **4444** (работает круглосуточно). 2. Специалист заблокирует старое устройство и поможет привязать новое. Источник: it_faq.pdf, стр. 2 | H9: 1 | I9: 1 | J9: 1
A10: 9 | B10: несколько фрагментов | C10: s09 | D10: Хочу месяц поработать из Испании. Можно ли и что для этого нужно? | E10: Можно не более 30 календарных дней в году (месяц из 31 дня уже превышает лимит); согласовать с HR и службой ИБ не позднее чем за 10 рабочих дней; подключаться только через VPN (клиент «TL Connect», заявка в ServiceDesk, «Доступы», выдаётся за 1 рабочий день). | F10: politika_udalennoy_raboty.pdf, стр. 3; it_faq.pdf, стр. 2 | G10: Да, поработать из Испании можно. Работа из-за пределов РФ допускается не более **30 календарных дней** в течение календарного года. Для этого необходимо: 1. Согласовать поездку с HR-отделом и службой информационной безопасности **не позднее чем за 10 рабочих дней** до её начала. 2. Подключаться к корпоративным системам за пределами офиса только через **корпоративный VPN**. Источник: politika_udalennoy_raboty.pdf, стр. 3 | H10: 0 | I10: 0 | J10: 1 | K10: та же ошибка, что у flash-lite: нет it_faq.pdf, стр. 2 (как получить VPN). Более сильная модель не помогла → агент делает один поиск и не ищет связанную тему
A11: 10 | B11: несколько фрагментов | C11: s10 | D11: За сколько нужно подать заявку на отпуск и за сколько — на разовый удалённый день? | E11: Отпуск — не позднее чем за 14 календарных дней; разовый удалённый день — не позднее чем за 1 рабочий день. | F11: reglament_otpuskov.pdf, стр. 2; politika_udalennoy_raboty.pdf, стр. 2 | G11: Заявку необходимо подавать в следующие сроки: * **На отпуск** — не позднее чем за **14 календарных дней** до даты начала отпуска (оформляется в HR-портале). * **На разовый удалённый день** — не позднее чем за **1 рабочий день** (для сотрудников офисного формата, оформляется в HR-портале). Источник: reglament_otpuskov.pdf, стр. 2 Источник: politika_udalennoy_raboty.pdf, стр. 2 | H11: 1 | I11: 1 | J11: 1
A12: 11 | B12: несколько фрагментов | C12: s11 | D12: Когда можно перейти на полностью удалённую работу и какие компенсации при этом положены? | E12: После успешного испытательного срока и по согласованию с директором по направлению; компенсация интернета 1 500 руб. в месяц (вместе с зарплатой). | F12: politika_udalennoy_raboty.pdf, стр. 1; politika_udalennoy_raboty.pdf, стр. 2 | G12: Перейти на полностью удалённый формат работы можно **после успешного прохождения испытательного срока** и по **согласованию с директором по направлению**. Изменение формата фиксируется в дополнительном соглашении к трудовому договору. При полностью удалённом формате сотрудникам выплачивается **компенсация расходов на домашний интернет в размере 1 500 рублей в месяц** (выплачивается вместе с заработной платой). Источник: politica_udalennoy_raboty.pdf, стр. 1, 2 | H12: 1 | I12: 0 | J12: 1 | K12: имя файла искажено: politica_… вместо politika_… — модель перепечатывает имя, а не копирует из метаданных
A13: 12 | B13: вне документов | C13: s12 | D13: Положен ли сотрудникам полис ДМС? | E13: Не знаю — в документах нет информации об этом. | F13: — | G13: Не знаю — в документах нет информации об этом. | H13: 1 | I13: 1 | J13: 1
A14: 13 | B14: вне документов | C14: s13 | D14: Сколько стоит парковка у офиса? | E14: Не знаю — в документах нет информации об этом. | F14: — | G14: Не знаю — в документах нет информации об этом. | H14: 1 | I14: 1 | J14: 1
A15: 14 | B15: вне документов (ловушка) | C15: s14 | D15: Сколько дней отпуска без сохранения зарплаты можно взять на обучение? | E15: В документах нет информации об отпуске на обучение. Допустимо упомянуть, что по семейным обстоятельствам дают до 5 дней, но нельзя выдавать это за ответ про обучение. | F15: — (рядом: reglament_otpuskov.pdf, стр. 2) | G15: Не знаю — в документах нет информации об этом. | H15: 1 | I15: 1 | J15: 1
A16: 15 | B16: память (после вопроса 1) | C16: s01 | D16: А для стажёров? | E16: Пропорционально отработанному времени: 2,33 календарного дня за каждый полный отработанный месяц. | F16: reglament_otpuskov.pdf, стр. 3 | G16: Стажёрам (сотрудникам по договору стажировки) отпуск предоставляется пропорционально отработанному времени: 2,33 календарного дня за каждый полный отработанный месяц. Источник: reglament_otpuskov.pdf, стр. 3 | H16: 1 | I16: 1 | J16: 1
G18: Итого (из 15) | H18: =SUM(H2:H16) -> 14 | I18: =SUM(I2:I16) -> 13 | J18: =SUM(J2:J16) -> 15
G19: Доля | H19: =IF(COUNT(H2:H16)=0,"",SUM(H2:H16)/COUNT(H2:H16)) -> 0.93333333 | I19: =IF(COUNT(I2:I16)=0,"",SUM(I2:I16)/COUNT(I2:I16)) -> 0.86666667 | J19: =IF(COUNT(J2:J16)=0,"",SUM(J2:J16)/COUNT(J2:J16)) -> 1
G20: Заполнено | H20: =COUNT(H2:H16) -> 15 | I20: =COUNT(I2:I16) -> 15 | J20: =COUNT(J2:J16) -> 15

Sheet Вопросы 7
A1: № | B1: Категория | C1: Сессия | D1: Вопрос | E1: Эталонный ответ | F1: Ожидаемый источник | G1: Фактический ответ | H1: correct | I1: source_ok | J1: no_hallucination | K1: Комментарий
A2: 1 | B2: прямой факт | C2: s01 | D2: Сколько календарных дней длится основной ежегодный отпуск? | E2: 28 календарных дней. | F2: reglament_otpuskov.pdf, стр. 1 | G2: Продолжительность ежегодного основного оплачиваемого отпуска составляет 28 календарных дней. Источник: reglament_otpuskov.pdf, стр. 1 | H2: 1 | I2: 1 | J2: 1
A3: 2 | B3: прямой факт | C3: s02 | D3: До какой даты утверждается график отпусков? | E3: Не позднее 15 декабря текущего года (на следующий год), утверждает генеральный директор. | F3: reglament_otpuskov.pdf, стр. 2 | G3: График отпусков на следующий календарный год утверждается генеральным директором не позднее 15 декабря текущего года. Источник: reglament_otpuskov.pdf, стр. 2 | H3: 1 | I3: 1 | J3: 1
A4: 3 | B4: прямой факт | C4: s03 | D4: Какие требования к длине пароля и как часто его нужно менять? | E4: Не менее 12 символов (заглавные, строчные буквы и цифры); смена каждые 90 дней; нельзя повторять 5 последних паролей. | F4: it_faq.pdf, стр. 1 | G4: Пароль должен содержать не менее 12 символов, включая заглавные и строчные буквы и цифры. Менять пароль нужно каждые 90 дней. Источник: it_faq.pdf, стр. 1 | H4: 1 | I4: 1 | J4: 1
A5: 4 | B5: прямой факт | C5: s04 | D5: Какие дни считаются командными при гибридном формате? | E5: Вторник и четверг — присутствие в офисе обязательно; всего не менее двух офисных дней в неделю. | F5: politika_udalennoy_raboty.pdf, стр. 1 | G5: При гибридном формате работы вторник и четверг являются командными днями, в эти дни присутствие в офисе обязательно. Источник: politika_udalennoy_raboty.pdf, стр. 1 | H5: 1 | I5: 1 | J5: 1
A6: 5 | B6: прямой факт | C6: s05 | D6: Какой срок реакции ServiceDesk на заявку о сломанном ноутбуке? | E6: 4 рабочих часа; заявка в категории «Оборудование». | F6: it_faq.pdf, стр. 3 | G6: Срок реакции ServiceDesk на заявку о сломанном ноутбуке составляет 4 рабочих часа. Источник: it_faq.pdf, стр. 3 | H6: 1 | I6: 1 | J6: 1
A7: 6 | B7: перефразирование | C7: s06 | D7: Когда мне перечислят деньги за отпуск? | E7: Отпускные перечисляются на зарплатную карту не позднее чем за 3 календарных дня до начала отпуска. | F7: reglament_otpuskov.pdf, стр. 3 | G7: Оплата отпуска (отпускные) перечисляется на зарплатную карту сотрудника не позднее чем за 3 календарных дня до начала отпуска. Источник: reglament_otpuskov.pdf, стр. 3 | H7: 1 | I7: 1 | J7: 1
A8: 7 | B8: перефразирование | C8: s07 | D8: Можно забрать экран из офиса, чтобы работать дома? | E8: Да, сотрудник гибридного или удалённого формата может забрать один монитор по акту передачи оборудования. | F8: it_faq.pdf, стр. 3 | G8: Да, сотрудник гибридного или удалённого формата может забрать домой один монитор из офиса по акту передачи оборудования. Источник: it_faq.pdf, стр. 3 | H8: 1 | I8: 1 | J8: 1
A9: 8 | B9: перефразирование | C9: s08 | D9: У меня украли смартфон, на котором стоит приложение для входа в почту. Что делать? | E9: Немедленно позвонить на линию поддержки по внутреннему номеру 4444 (круглосуточно): заблокируют старое устройство и помогут привязать новое. | F9: it_faq.pdf, стр. 2 | G9: Немедленно позвоните на линию поддержки по внутреннему номеру 4444 (работает круглосуточно). Специалист заблокирует старое устройство и поможет привязать новое. Источник: it_faq.pdf, стр. 2 | H9: 1 | I9: 1 | J9: 1
A10: 9 | B10: несколько фрагментов | C10: s09 | D10: Хочу месяц поработать из Испании. Можно ли и что для этого нужно? | E10: Можно не более 30 календарных дней в году (месяц из 31 дня уже превышает лимит); согласовать с HR и службой ИБ не позднее чем за 10 рабочих дней; подключаться только через VPN (клиент «TL Connect», заявка в ServiceDesk, «Доступы», выдаётся за 1 рабочий день). | F10: politika_udalennoy_raboty.pdf, стр. 3; it_faq.pdf, стр. 2 | G10: Да, поработать из-за рубежа (в том числе из Испании) можно. Для этого необходимо соблюдать следующие условия и выполнить требования: 1. Работа из-за пределов Российской Федерации допускается на срок не более 30 календарных дней в течение календарного года. 2. Поездку нужно обязательно согласовать с HR-отделом и службой информационной безопасности не позднее чем за 10 рабочих дней до её начала. 3. При подключении к корпоративным системам за пределами офиса разрешено использовать только корпоративный VPN. Источник: politika_udalennoy_raboty.pdf, стр. 3 | H10: 0 | I10: 0 | J10: 1 | K10: №9 не исправлен: VPN упомянут как требование, но второго поиска «как получить VPN» нет (проверить в логе число вызовов search_docs)
A11: 10 | B11: несколько фрагментов | C11: s10 | D11: За сколько нужно подать заявку на отпуск и за сколько — на разовый удалённый день? | E11: Отпуск — не позднее чем за 14 календарных дней; разовый удалённый день — не позднее чем за 1 рабочий день. | F11: reglament_otpuskov.pdf, стр. 2; politika_udalennoy_raboty.pdf, стр. 2 | G11: Заявление на отпуск нужно подать не позднее чем за 14 календарных дней до даты начала отпуска. Заявка на разовый удаленный день подается не позднее чем за 1 рабочий день. Источник: reglament_otpuskov.pdf, стр. 2 Источник: politika_udalennoy_raboty.pdf, стр. 2 | H11: 1 | I11: 1 | J11: 1
A12: 11 | B12: несколько фрагментов | C12: s11 | D12: Когда можно перейти на полностью удалённую работу и какие компенсации при этом положены? | E12: После успешного испытательного срока и по согласованию с директором по направлению; компенсация интернета 1 500 руб. в месяц (вместе с зарплатой). | F12: politika_udalennoy_raboty.pdf, стр. 1; politika_udalennoy_raboty.pdf, стр. 2 | G12: Переход на полностью удаленный формат возможен только после успешного прохождения испытательного срока и по согласованию с директором по направлению. Данный формат фиксируется в дополнительном соглашении к трудовому договору. Сотрудникам полностью удаленного формата компания компенсирует расходы на домашний интернет в размере 1 500 рублей в месяц. Эта компенсация выплачивается вместе с заработной платой. Источник: politika_udalennoy_raboty.pdf, стр. 1 Источник: politika_udalennoy_raboty.pdf, стр. 2 | H12: 1 | I12: 1 | J12: 1
A13: 12 | B13: вне документов | C13: s12 | D13: Положен ли сотрудникам полис ДМС? | E13: Не знаю — в документах нет информации об этом. | F13: — | G13: Не знаю — в документах нет информации об этом. | H13: 1 | I13: 1 | J13: 1
A14: 13 | B14: вне документов | C14: s13 | D14: Сколько стоит парковка у офиса? | E14: Не знаю — в документах нет информации об этом. | F14: — | G14: Не знаю — в документах нет информации об этом. | H14: 1 | I14: 1 | J14: 1
A15: 14 | B15: вне документов (ловушка) | C15: s14 | D15: Сколько дней отпуска без сохранения зарплаты можно взять на обучение? | E15: В документах нет информации об отпуске на обучение. Допустимо упомянуть, что по семейным обстоятельствам дают до 5 дней, но нельзя выдавать это за ответ про обучение. | F15: — (рядом: reglament_otpuskov.pdf, стр. 2) | G15: Не знаю — в документах нет информации об этом. | H15: 1 | I15: 1 | J15: 1 | K15: отказ без источника — правило 4 нового промпта работает
